Workbook

Sheet Sheet1
B2: NORTHERN HEMISPHERE COMMAND
B3: Field terminal — offline clearance check.
B6: Flag
B8: STATUS | C8: =IF(Sheet3!$BX$2=1,"● ACCESS GRANTED","● ACCESS DENIED") -> ● ACCESS DENIED

Sheet Sheet2
A1: k1 | B1: k2 | C1: k3 | D1: k4 | F1: k5 | H1: k6
A2: 0 | B2: 3614090360 | C2: 7 | D2: 0 | F2: 214 | H2: =LEFT(Sheet1!$C$6&REPT("?",30),30) -> ??????????????????????????????
A3: 1 | B3: 3905402710 | C3: 12 | D3: 1 | F3: 149
A4: 2 | B4: 606105819 | C4: 17 | D4: 2 | F4: 200
A5: 3 | B5: 3250441966 | C5: 22 | D5: 3 | F5: 192
A6: 4 | B6: 4118548399 | C6: 7 | D6: 4 | F6: 250
A7: 5 | B7: 1200080426 | C7: 12 | D7: 5 | F7: 214
A8: 6 | B8: 2821735955 | C8: 17 | D8: 6 | F8: 203
A9: 7 | B9: 4249261313 | C9: 22 | D9: 7 | F9: 150
A10: 8 | B10: 1770035416 | C10: 7 | D10: 8 | F10: 145
A11: 9 | B11: 2336552879 | C11: 12 | D11: 9 | F11: 206
A12: 10 | B12: 4294925233 | C12: 17 | D12: 10 | F12: 220
A13: 11 | B13: 2304563134 | C13: 22 | D13: 11 | F13: 250
A14: 12 | B14: 1804603682 | C14: 7 | D14: 12 | F14: 214
... A17: 15 | B17: 1236535329 | C17: 22 | D17: 15 | F17: 209
A18: 16 | B18: 4129170786 | C18: 5 | D18: 1
A19: 17 | B19: 3225465664 | C19: 9 | D19: 6
A20: 18 | B20: 643717713 | C20: 14 | D20: 11
A21: 19 | B21: 3921069994 | C21: 20 | D21: 0
A22: 20 | B22: 3593408605 | C22: 5 | D22: 5
A23: 21 | B23: 38016083 | C23: 9 | D23: 10
A24: 22 | B24: 3634488961 | C24: 14 | D24: 15
A25: 23 | B25: 3889429448 | C25: 20 | D25: 4
A26: 24 | B26: 568446438 | C26: 5 | D26: 9
A27: 25 | B27: 3275163606 | C27: 9 | D27: 14
A28: 26 | B28: 4107603335 | C28: 14 | D28: 3
A29: 27 | B29: 1163531501 | C29: 20 | D29: 8
... A65: 63 | B65: 3951481745 | C65: 21 | D65: 9

Sheet Sheet3
A1: c1 | B1: c2 | C1: c3 | D1: c4 | E1: c5 | F1: c6 | G1: c7 | H1: c8 | I1: c9 | J1: c10 | K1: c11 | L1: c12 | M1: c13 | N1: c14 | O1: c15 | P1: c16 | Q1: c17 | R1: c18 | S1: c19 | T1: c20 | U1: c21 | V1: c22 | W1: c23 | X1: c24 | Y1: c25 | Z1: c26 | AA1: c27 | AB1: c28 | AC1: c29 | AD1: c30 | AE1: c31 | AF1: c32 | AG1: c33 | AH1: c34 | AI1: c35 | AJ1: c36 | AK1: c37 | AL1: c38 | AM1: c39 | AN1: c40 | AO1: c41 | AP1: c42 | AQ1: c43 | AR1: c44 | AS1: c45 | AT1: c46 | AU1: c47 | AV1: c48 | AW1: c49 | AX1: c50 | AY1: c51 | AZ1: c52 | BA1: c53 | BB1: c54 | BC1: c55 | BD1: c56 | BE1: c57 | BF1: c58 | BG1: c59 | BH1: c60 | BI1: c61 | BJ1: c62 | BK1: c63 | BL1: c64 | BM1: c65 | BN1: c66 | BO1: c67 | BP1: c68 | BQ1: c69 | BR1: c70 | BS1: c71 | BT1: c72 | BU1: c73 | BV1: c74 | BW1: c75 | BX1: c76
A2: 1 | B2: =COUNT(Sheet2!$F$2:$F$17)+COUNT($C2:$E2) -> 19 | C2: =CODE(MID(Sheet2!$H$2,$A2,1)) -> 63 | D2: =CODE(MID(Sheet2!$H$2,$A2+10,1)) -> 63 | E2: =CODE(MID(Sheet2!$H$2,$A2+20,1)) -> 63 | F2: 128 | G2: 0 | H2: 0 | I2: 0 | J2: 0 | K2: 0 | L2: 0 | M2: 0 | N2: 0 | O2: 0 | P2: 0 | Q2: 0 | R2: 0 | S2: 0 | T2: 0 | U2: 0 | V2: 0 | W2: 0 | X2: 0 | Y2: 0 | Z2: 0 | AA2: 0 | AB2: 0 | AC2: 0 | AD2: 0 | AE2: 0 | AF2: 0 | AG2: 0 | AH2: 0 | AI2: 0 | AJ2: 0 | AK2: 0 | AL2: 0 | AM2: 0 | AN2: 0 | AO2: 0 | AP2: 0 | AQ2: =MOD(INT($B2*8/256^0),256) -> 152 | AR2: =MOD(INT($B2*8/256^1),256) -> 0 | AS2: =MOD(INT($B2*8/256^2),256) -> 0 | AT2: =MOD(INT($B2*8/256^3),256) -> 0 | AU2: =MOD(INT($B2*8/256^4),256) -> 0 | AV2: =MOD(INT($B2*8/256^5),256) -> 0 | AW2: =MOD(INT($B2*8/256^6),256) -> 0 | AX2: =MOD(INT($B2*8/256^7),256) -> 0 | AY2: =_xlfn.BITXOR(Sheet2!$F$2,165)+_xlfn.BITXOR(Sheet2!$F$3,165)*256+_xlfn.BITXOR(Sheet2!$F$4,165)*65536+_xlfn.BITXOR(Sheet2!$F$5,165)*16777216 -> 1701654643 | AZ2: =_xlfn.BITXOR(Sheet2!$F$6,165)+_xlfn.BITXOR(Sheet2!$F$7,165)*256+_xlfn.BITXOR(Sheet2!$F$8,165)*65536+_xlfn.BITXOR(Sheet2!$F$9,165)*16777216 -> 862876511 | BA2: =_xlfn.BITXOR(Sheet2!$F$10,165)+_xlfn.BITXOR(Sheet2!$F$11,165)*256+_xlfn.BITXOR(Sheet2!$F$12,165)*65536+_xlfn.BITXOR(Sheet2!$F$13,165)*16777216 -> 1601792820 | BB2: =_xlfn.BITXOR(Sheet2!$F$14,165)+_xlfn.BITXOR(Sheet2!$F$15,165)*256+_xlfn.BITXOR(Sheet2!$F$16,165)*65536+_xlfn.BITXOR(Sheet2!$F$17,165)*16777216 -> 1953248371 | BC2: =C2+D2*256+E2*65536+F2*16777216 -> 2151628607 | BD2: =G2+H2*256+I2*65536+J2*16777216 -> 0 | BE2: =K2+L2*256+M2*65536+N2*16777216 -> 0 | BF2: =O2+P2*256+Q2*65536+R2*16777216 -> 0 | BG2: =S2+T2*256+U2*65536+V2*16777216 -> 0 | BH2: =W2+X2*256+Y2*65536+Z2*16777216 -> 0 | BI2: =AA2+AB2*256+AC2*65536+AD2*16777216 -> 0 | BJ2: =AE2+AF2*256+AG2*65536+AH2*16777216 -> 0 | BK2: =AI2+AJ2*256+AK2*65536+AL2*16777216 -> 0 | BL2: =AM2+AN2*256+AO2*65536+AP2*16777216 -> 0 | BM2: =AQ2+AR2*256+AS2*65536+AT2*16777216 -> 152 | BN2: =AU2+AV2*256+AW2*65536+AX2*16777216 -> 0 | BO2: =MOD(1732584193+Sheet4!$J$66,4294967296) -> 2864597674 | BP2: =MOD(4023233417+Sheet4!$K$66,4294967296) -> 3283020593 | BQ2: =MOD(2562383102+Sheet4!$L$66,4294967296) -> 3317144422 | BR2: =MOD(271733878+Sheet4!$M$66,4294967296) -> 2031522474 | BS2: 4072117587 | BT2: 1120387196 | BU2: 2102578019 | BV2: 85756587 | BW2: =IF(AND(BO2=BS2,BP2=BT2,BQ2=BU2,BR2=BV2),1,0) -> 0 | BX2: =IF(AND(LEN(Sheet1!$C$6)=30,SUM($BW$2:$BW$11)=10),1,0) -> 0
A3: 2 | B3: =COUNT(Sheet2!$F$2:$F$17)+COUNT($C3:$E3) -> 19 | C3: =CODE(MID(Sheet2!$H$2,$A3,1)) -> 63 | D3: =CODE(MID(Sheet2!$H$2,$A3+10,1)) -> 63 | E3: =CODE(MID(Sheet2!$H$2,$A3+20,1)) -> 63 | F3: 128 | G3: 0 | H3: 0 | I3: 0 | J3: 0 | K3: 0 | L3: 0 | M3: 0 | N3: 0 | O3: 0 | P3: 0 | Q3: 0 | R3: 0 | S3: 0 | T3: 0 | U3: 0 | V3: 0 | W3: 0 | X3: 0 | Y3: 0 | Z3: 0 | AA3: 0 | AB3: 0 | AC3: 0 | AD3: 0 | AE3: 0 | AF3: 0 | AG3: 0 | AH3: 0 | AI3: 0 | AJ3: 0 | AK3: 0 | AL3: 0 | AM3: 0 | AN3: 0 | AO3: 0 | AP3: 0 | AQ3: =MOD(INT($B3*8/256^0),256) -> 152 | AR3: =MOD(INT($B3*8/256^1),256) -> 0 | AS3: =MOD(INT($B3*8/256^2),256) -> 0 | AT3: =MOD(INT($B3*8/256^3),256) -> 0 | AU3: =MOD(INT($B3*8/256^4),256) -> 0 | AV3: =MOD(INT($B3*8/256^5),256) -> 0 | AW3: =MOD(INT($B3*8/256^6),256) -> 0 | AX3: =MOD(INT($B3*8/256^7),256) -> 0 | AY3: =_xlfn.BITXOR(Sheet2!$F$2,165)+_xlfn.BITXOR(Sheet2!$F$3,165)*256+_xlfn.BITXOR(Sheet2!$F$4,165)*65536+_xlfn.BITXOR(Sheet2!$F$5,165)*16777216 -> 1701654643 | AZ3: =_xlfn.BITXOR(Sheet2!$F$6,165)+_xlfn.BITXOR(Sheet2!$F$7,165)*256+_xlfn.BITXOR(Sheet2!$F$8,165)*65536+_xlfn.BITXOR(Sheet2!$F$9,165)*16777216 -> 862876511 | BA3: =_xlfn.BITXOR(Sheet2!$F$10,165)+_xlfn.BITXOR(Sheet2!$F$11,165)*256+_xlfn.BITXOR(Sheet2!$F$12,165)*65536+_xlfn.BITXOR(Sheet2!$F$13,165)*16777216 -> 1601792820 | BB3: =_xlfn.BITXOR(Sheet2!$F$14,165)+_xlfn.BITXOR(Sheet2!$F$15,165)*256+_xlfn.BITXOR(Sheet2!$F$16,165)*65536+_xlfn.BITXOR(Sheet2!$F$17,165)*16777216 -> 1953248371 | BC3: =C3+D3*256+E3*65536+F3*16777216 -> 2151628607 | BD3: =G3+H3*256+I3*65536+J3*16777216 -> 0 | BE3: =K3+L3*256+M3*65536+N3*16777216 -> 0 | BF3: =O3+P3*256+Q3*65536+R3*16777216 -> 0 | BG3: =S3+T3*256+U3*65536+V3*16777216 -> 0 | BH3: =W3+X3*256+Y3*65536+Z3*16777216 -> 0 | BI3: =AA3+AB3*256+AC3*65536+AD3*16777216 -> 0 | BJ3: =AE3+AF3*256+AG3*65536+AH3*16777216 -> 0 | BK3: =AI3+AJ3*256+AK3*65536+AL3*16777216 -> 0 | BL3: =AM3+AN3*256+AO3*65536+AP3*16777216 -> 0 | BM3: =AQ3+AR3*256+AS3*65536+AT3*16777216 -> 152 | BN3: =AU3+AV3*256+AW3*65536+AX3*16777216 -> 0 | BO3: =MOD(1732584193+Sheet4!$J$131,4294967296) -> 2864597674 | BP3: =MOD(4023233417+Sheet4!$K$131,4294967296) -> 3283020593 | BQ3: =MOD(2562383102+Sheet4!$L$131,4294967296) -> 3317144422 | BR3: =MOD(271733878+Sheet4!$M$131,4294967296) -> 2031522474 | BS3: 3002749583 | BT3: 3716679707 | BU3: 3074522701 | BV3: 1912839214 | BW3: =IF(AND(BO3=BS3,BP3=BT3,BQ3=BU3,BR3=BV3),1,0) -> 0
A4: 3 | B4: =COUNT(Sheet2!$F$2:$F$17)+COUNT($C4:$E4) -> 19 | C4: =CODE(MID(Sheet2!$H$2,$A4,1)) -> 63 | D4: =CODE(MID(Sheet2!$H$2,$A4+10,1)) -> 63 | E4: =CODE(MID(Sheet2!$H$2,$A4+20,1)) -> 63 | F4: 128 | G4: 0 | H4: 0 | I4: 0 | J4: 0 | K4: 0 | L4: 0 | M4: 0 | N4: 0 | O4: 0 | P4: 0 | Q4: 0 | R4: 0 | S4: 0 | T4: 0 | U4: 0 | V4: 0 | W4: 0 | X4: 0 | Y4: 0 | Z4: 0 | AA4: 0 | AB4: 0 | AC4: 0 | AD4: 0 | AE4: 0 | AF4: 0 | AG4: 0 | AH4: 0 | AI4: 0 | AJ4: 0 | AK4: 0 | AL4: 0 | AM4: 0 | AN4: 0 | AO4: 0 | AP4: 0 | AQ4: =MOD(INT($B4*8/256^0),256) -> 152 | AR4: =MOD(INT($B4*8/256^1),256) -> 0 | AS4: =MOD(INT($B4*8/256^2),256) -> 0 | AT4: =MOD(INT($B4*8/256^3),256) -> 0 | AU4: =MOD(INT($B4*8/256^4),256) -> 0 | AV4: =MOD(INT($B4*8/256^5),256) -> 0 | AW4: =MOD(INT($B4*8/256^6),256) -> 0 | AX4: =MOD(INT($B4*8/256^7),256) -> 0 | AY4: =_xlfn.BITXOR(Sheet2!$F$2,165)+_xlfn.BITXOR(Sheet2!$F$3,165)*256+_xlfn.BITXOR(Sheet2!$F$4,165)*65536+_xlfn.BITXOR(Sheet2!$F$5,165)*16777216 -> 1701654643 | AZ4: =_xlfn.BITXOR(Sheet2!$F$6,165)+_xlfn.BITXOR(Sheet2!$F$7,165)*256+_xlfn.BITXOR(Sheet2!$F$8,165)*65536+_xlfn.BITXOR(Sheet2!$F$9,165)*16777216 -> 862876511 | BA4: =_xlfn.BITXOR(Sheet2!$F$10,165)+_xlfn.BITXOR(Sheet2!$F$11,165)*256+_xlfn.BITXOR(Sheet2!$F$12,165)*65536+_xlfn.BITXOR(Sheet2!$F$13,165)*16777216 -> 1601792820 | BB4: =_xlfn.BITXOR(Sheet2!$F$14,165)+_xlfn.BITXOR(Sheet2!$F$15,165)*256+_xlfn.BITXOR(Sheet2!$F$16,165)*65536+_xlfn.BITXOR(Sheet2!$F$17,165)*16777216 -> 1953248371 | BC4: =C4+D4*256+E4*65536+F4*16777216 -> 2151628607 | BD4: =G4+H4*256+I4*65536+J4*16777216 -> 0 | BE4: =K4+L4*256+M4*65536+N4*16777216 -> 0 | BF4: =O4+P4*256+Q4*65536+R4*16777216 -> 0 | BG4: =S4+T4*256+U4*65536+V4*16777216 -> 0 | BH4: =W4+X4*256+Y4*65536+Z4*16777216 -> 0 | BI4: =AA4+AB4*256+AC4*65536+AD4*16777216 -> 0 | BJ4: =AE4+AF4*256+AG4*65536+AH4*16777216 -> 0 | BK4: =AI4+AJ4*256+AK4*65536+AL4*16777216 -> 0 | BL4: =AM4+AN4*256+AO4*65536+AP4*16777216 -> 0 | BM4: =AQ4+AR4*256+AS4*65536+AT4*16777216 -> 152 | BN4: =AU4+AV4*256+AW4*65536+AX4*16777216 -> 0 | BO4: =MOD(1732584193+Sheet4!$J$196,4294967296) -> 2864597674 | BP4: =MOD(4023233417+Sheet4!$K$196,4294967296) -> 3283020593 | BQ4: =MOD(2562383102+Sheet4!$L$196,4294967296) -> 3317144422 | BR4: =MOD(271733878+Sheet4!$M$196,4294967296) -> 2031522474 | BS4: 1202946202 | BT4: 3060285146 | BU4: 3794539838 | BV4: 3225098655 | BW4: =IF(AND(BO4=BS4,BP4=BT4,BQ4=BU4,BR4=BV4),1,0) -> 0
A5: 4 | B5: =COUNT(Sheet2!$F$2:$F$17)+COUNT($C5:$E5) -> 19 | C5: =CODE(MID(Sheet2!$H$2,$A5,1)) -> 63 | D5: =CODE(MID(Sheet2!$H$2,$A5+10,1)) -> 63 | E5: =CODE(MID(Sheet2!$H$2,$A5+20,1)) -> 63 | F5: 128 | G5: 0 | H5: 0 | I5: 0 | J5: 0 | K5: 0 | L5: 0 | M5: 0 | N5: 0 | O5: 0 | P5: 0 | Q5: 0 | R5: 0 | S5: 0 | T5: 0 | U5: 0 | V5: 0 | W5: 0 | X5: 0 | Y5: 0 | Z5: 0 | AA5: 0 | AB5: 0 | AC5: 0 | AD5: 0 | AE5: 0 | AF5: 0 | AG5: 0 | AH5: 0 | AI5: 0 | AJ5: 0 | AK5: 0 | AL5: 0 | AM5: 0 | AN5: 0 | AO5: 0 | AP5: 0 | AQ5: =MOD(INT($B5*8/256^0),256) -> 152 | AR5: =MOD(INT($B5*8/256^1),256) -> 0 | AS5: =MOD(INT($B5*8/256^2),256) -> 0 | AT5: =MOD(INT($B5*8/256^3),256) -> 0 | AU5: =MOD(INT($B5*8/256^4),256) -> 0 | AV5: =MOD(INT($B5*8/256^5),256) -> 0 | AW5: =MOD(INT($B5*8/256^6),256) -> 0 | AX5: =MOD(INT($B5*8/256^7),256) -> 0 | AY5: =_xlfn.BITXOR(Sheet2!$F$2,165)+_xlfn.BITXOR(Sheet2!$F$3,165)*256+_xlfn.BITXOR(Sheet2!$F$4,165)*65536+_xlfn.BITXOR(Sheet2!$F$5,165)*16777216 -> 1701654643 | AZ5: =_xlfn.BITXOR(Sheet2!$F$6,165)+_xlfn.BITXOR(Sheet2!$F$7,165)*256+_xlfn.BITXOR(Sheet2!$F$8,165)*65536+_xlfn.BITXOR(Sheet2!$F$9,165)*16777216 -> 862876511 | BA5: =_xlfn.BITXOR(Sheet2!$F$10,165)+_xlfn.BITXOR(Sheet2!$F$11,165)*256+_xlfn.BITXOR(Sheet2!$F$12,165)*65536+_xlfn.BITXOR(Sheet2!$F$13,165)*16777216 -> 1601792820 | BB5: =_xlfn.BITXOR(Sheet2!$F$14,165)+_xlfn.BITXOR(Sheet2!$F$15,165)*256+_xlfn.BITXOR(Sheet2!$F$16,165)*65536+_xlfn.BITXOR(Sheet2!$F$17,165)*16777216 -> 1953248371 | BC5: =C5+D5*256+E5*65536+F5*16777216 -> 2151628607 | BD5: =G5+H5*256+I5*65536+J5*16777216 -> 0 | BE5: =K5+L5*256+M5*65536+N5*16777216 -> 0 | BF5: =O5+P5*256+Q5*65536+R5*16777216 -> 0 | BG5: =S5+T5*256+U5*65536+V5*16777216 -> 0 | BH5: =W5+X5*256+Y5*65536+Z5*16777216 -> 0 | BI5: =AA5+AB5*256+AC5*65536+AD5*16777216 -> 0 | BJ5: =AE5+AF5*256+AG5*65536+AH5*16777216 -> 0 | BK5: =AI5+AJ5*256+AK5*65536+AL5*16777216 -> 0 | BL5: =AM5+AN5*256+AO5*65536+AP5*16777216 -> 0 | BM5: =AQ5+AR5*256+AS5*65536+AT5*16777216 -> 152 | BN5: =AU5+AV5*256+AW5*65536+AX5*16777216 -> 0 | BO5: =MOD(1732584193+Sheet4!$J$261,4294967296) -> 2864597674 | BP5: =MOD(4023233417+Sheet4!$K$261,4294967296) -> 3283020593 | BQ5: =MOD(2562383102+Sheet4!$L$261,4294967296) -> 3317144422 | BR5: =MOD(271733878+Sheet4!$M$261,4294967296) -> 2031522474 | BS5: 4005615615 | BT5: 2391617212 | BU5: 2576942536 | BV5: 2140002521 | BW5: =IF(AND(BO5=BS5,BP5=BT5,BQ5=BU5,BR5=BV5),1,0) -> 0
A6: 5 | B6: =COUNT(Sheet2!$F$2:$F$17)+COUNT($C6:$E6) -> 19 | C6: =CODE(MID(Sheet2!$H$2,$A6,1)) -> 63 | D6: =CODE(MID(Sheet2!$H$2,$A6+10,1)) -> 63 | E6: =CODE(MID(Sheet2!$H$2,$A6+20,1)) -> 63 | F6: 128 | G6: 0 | H6: 0 | I6: 0 | J6: 0 | K6: 0 | L6: 0 | M6: 0 | N6: 0 | O6: 0 | P6: 0 | Q6: 0 | R6: 0 | S6: 0 | T6: 0 | U6: 0 | V6: 0 | W6: 0 | X6: 0 | Y6: 0 | Z6: 0 | AA6: 0 | AB6: 0 | AC6: 0 | AD6: 0 | AE6: 0 | AF6: 0 | AG6: 0 | AH6: 0 | AI6: 0 | AJ6: 0 | AK6: 0 | AL6: 0 | AM6: 0 | AN6: 0 | AO6: 0 | AP6: 0 | AQ6: =MOD(INT($B6*8/256^0),256) -> 152 | AR6: =MOD(INT($B6*8/256^1),256) -> 0 | AS6: =MOD(INT($B6*8/256^2),256) -> 0 | AT6: =MOD(INT($B6*8/256^3),256) -> 0 | AU6: =MOD(INT($B6*8/256^4),256) -> 0 | AV6: =MOD(INT($B6*8/256^5),256) -> 0 | AW6: =MOD(INT($B6*8/256^6),256) -> 0 | AX6: =MOD(INT($B6*8/256^7),256) -> 0 | AY6: =_xlfn.BITXOR(Sheet2!$F$2,165)+_xlfn.BITXOR(Sheet2!$F$3,165)*256+_xlfn.BITXOR(Sheet2!$F$4,165)*65536+_xlfn.BITXOR(Sheet2!$F$5,165)*16777216 -> 1701654643 | AZ6: =_xlfn.BITXOR(Sheet2!$F$6,165)+_xlfn.BITXOR(Sheet2!$F$7,165)*256+_xlfn.BITXOR(Sheet2!$F$8,165)*65536+_xlfn.BITXOR(Sheet2!$F$9,165)*16777216 -> 862876511 | BA6: =_xlfn.BITXOR(Sheet2!$F$10,165)+_xlfn.BITXOR(Sheet2!$F$11,165)*256+_xlfn.BITXOR(Sheet2!$F$12,165)*65536+_xlfn.BITXOR(Sheet2!$F$13,165)*16777216 -> 1601792820 | BB6: =_xlfn.BITXOR(Sheet2!$F$14,165)+_xlfn.BITXOR(Sheet2!$F$15,165)*256+_xlfn.BITXOR(Sheet2!$F$16,165)*65536+_xlfn.BITXOR(Sheet2!$F$17,165)*16777216 -> 1953248371 | BC6: =C6+D6*256+E6*65536+F6*16777216 -> 2151628607 | BD6: =G6+H6*256+I6*65536+J6*16777216 -> 0 | BE6: =K6+L6*256+M6*65536+N6*16777216 -> 0 | BF6: =O6+P6*256+Q6*65536+R6*16777216 -> 0 | BG6: =S6+T6*256+U6*65536+V6*16777216 -> 0 | BH6: =W6+X6*256+Y6*65536+Z6*16777216 -> 0 | BI6: =AA6+AB6*256+AC6*65536+AD6*16777216 -> 0 | BJ6: =AE6+AF6*256+AG6*65536+AH6*16777216 -> 0 | BK6: =AI6+AJ6*256+AK6*65536+AL6*16777216 -> 0 | BL6: =AM6+AN6*256+AO6*65536+AP6*16777216 -> 0 | BM6: =AQ6+AR6*256+AS6*65536+AT6*16777216 -> 152 | BN6: =AU6+AV6*256+AW6*65536+AX6*16777216 -> 0 | BO6: =MOD(1732584193+Sheet4!$J$326,4294967296) -> 2864597674 | BP6: =MOD(4023233417+Sheet4!$K$326,4294967296) -> 3283020593 | BQ6: =MOD(2562383102+Sheet4!$L$326,4294967296) -> 3317144422 | BR6: =MOD(271733878+Sheet4!$M$326,4294967296) -> 2031522474 | BS6: 1783887626 | BT6: 3622230939 | BU6: 1267188250 | BV6: 2483512918 | BW6: =IF(AND(BO6=BS6,BP6=BT6,BQ6=BU6,BR6=BV6),1,0) -> 0
A7: 6 | B7: =COUNT(Sheet2!$F$2:$F$17)+COUNT($C7:$E7) -> 19 | C7: =CODE(MID(Sheet2!$H$2,$A7,1)) -> 63 | D7: =CODE(MID(Sheet2!$H$2,$A7+10,1)) -> 63 | E7: =CODE(MID(Sheet2!$H$2,$A7+20,1)) -> 63 | F7: 128 | G7: 0 | H7: 0 | I7: 0 | J7: 0 | K7: 0 | L7: 0 | M7: 0 | N7: 0 | O7: 0 | P7: 0 | Q7: 0 | R7: 0 | S7: 0 | T7: 0 | U7: 0 | V7: 0 | W7: 0 | X7: 0 | Y7: 0 | Z7: 0 | AA7: 0 | AB7: 0 | AC7: 0 | AD7: 0 | AE7: 0 | AF7: 0 | AG7: 0 | AH7: 0 | AI7: 0 | AJ7: 0 | AK7: 0 | AL7: 0 | AM7: 0 | AN7: 0 | AO7: 0 | AP7: 0 | AQ7: =MOD(INT($B7*8/256^0),256) -> 152 | AR7: =MOD(INT($B7*8/256^1),256) -> 0 | AS7: =MOD(INT($B7*8/256^2),256) -> 0 | AT7: =MOD(INT($B7*8/256^3),256) -> 0 | AU7: =MOD(INT($B7*8/256^4),256) -> 0 | AV7: =MOD(INT($B7*8/256^5),256) -> 0 | AW7: =MOD(INT($B7*8/256^6),256) -> 0 | AX7: =MOD(INT($B7*8/256^7),256) -> 0 | AY7: =_xlfn.BITXOR(Sheet2!$F$2,165)+_xlfn.BITXOR(Sheet2!$F$3,165)*256+_xlfn.BITXOR(Sheet2!$F$4,165)*65536+_xlfn.BITXOR(Sheet2!$F$5,165)*16777216 -> 1701654643 | AZ7: =_xlfn.BITXOR(Sheet2!$F$6,165)+_xlfn.BITXOR(Sheet2!$F$7,165)*256+_xlfn.BITXOR(Sheet2!$F$8,165)*65536+_xlfn.BITXOR(Sheet2!$F$9,165)*16777216 -> 862876511 | BA7: =_xlfn.BITXOR(Sheet2!$F$10,165)+_xlfn.BITXOR(Sheet2!$F$11,165)*256+_xlfn.BITXOR(Sheet2!$F$12,165)*65536+_xlfn.BITXOR(Sheet2!$F$13,165)*16777216 -> 1601792820 | BB7: =_xlfn.BITXOR(Sheet2!$F$14,165)+_xlfn.BITXOR(Sheet2!$F$15,165)*256+_xlfn.BITXOR(Sheet2!$F$16,165)*65536+_xlfn.BITXOR(Sheet2!$F$17,165)*16777216 -> 1953248371 | BC7: =C7+D7*256+E7*65536+F7*16777216 -> 2151628607 | BD7: =G7+H7*256+I7*65536+J7*16777216 -> 0 | BE7: =K7+L7*256+M7*65536+N7*16777216 -> 0 | BF7: =O7+P7*256+Q7*65536+R7*16777216 -> 0 | BG7: =S7+T7*256+U7*65536+V7*16777216 -> 0 | BH7: =W7+X7*256+Y7*65536+Z7*16777216 -> 0 | BI7: =AA7+AB7*256+AC7*65536+AD7*16777216 -> 0 | BJ7: =AE7+AF7*256+AG7*65536+AH7*16777216 -> 0 | BK7: =AI7+AJ7*256+AK7*65536+AL7*16777216 -> 0 | BL7: =AM7+AN7*256+AO7*65536+AP7*16777216 -> 0 | BM7: =AQ7+AR7*256+AS7*65536+AT7*16777216 -> 152 | BN7: =AU7+AV7*256+AW7*65536+AX7*16777216 -> 0 | BO7: =MOD(1732584193+Sheet4!$J$391,4294967296) -> 2864597674 | BP7: =MOD(4023233417+Sheet4!$K$391,4294967296) -> 3283020593 | BQ7: =MOD(2562383102+Sheet4!$L$391,4294967296) -> 3317144422 | BR7: =MOD(271733878+Sheet4!$M$391,4294967296) -> 2031522474 | BS7: 3971983597 | BT7: 866610566 | BU7: 1921144098 | BV7: 402180923 | BW7: =IF(AND(BO7=BS7,BP7=BT7,BQ7=BU7,BR7=BV7),1,0) -> 0
A8: 7 | B8: =COUNT(Sheet2!$F$2:$F$17)+COUNT($C8:$E8) -> 19 | C8: =CODE(MID(Sheet2!$H$2,$A8,1)) -> 63 | D8: =CODE(MID(Sheet2!$H$2,$A8+10,1)) -> 63 | E8: =CODE(MID(Sheet2!$H$2,$A8+20,1)) -> 63 | F8: 128 | G8: 0 | H8: 0 | I8: 0 | J8: 0 | K8: 0 | L8: 0 | M8: 0 | N8: 0 | O8: 0 | P8: 0 | Q8: 0 | R8: 0 | S8: 0 | T8: 0 | U8: 0 | V8: 0 | W8: 0 | X8: 0 | Y8: 0 | Z8: 0 | AA8: 0 | AB8: 0 | AC8: 0 | AD8: 0 | AE8: 0 | AF8: 0 | AG8: 0 | AH8: 0 | AI8: 0 | AJ8: 0 | AK8: 0 | AL8: 0 | AM8: 0 | AN8: 0 | AO8: 0 | AP8: 0 | AQ8: =MOD(INT($B8*8/256^0),256) -> 152 | AR8: =MOD(INT($B8*8/256^1),256) -> 0 | AS8: =MOD(INT($B8*8/256^2),256) -> 0 | AT8: =MOD(INT($B8*8/256^3),256) -> 0 | AU8: =MOD(INT($B8*8/256^4),256) -> 0 | AV8: =MOD(INT($B8*8/256^5),256) -> 0 | AW8: =MOD(INT($B8*8/256^6),256) -> 0 | AX8: =MOD(INT($B8*8/256^7),256) -> 0 | AY8: =_xlfn.BITXOR(Sheet2!$F$2,165)+_xlfn.BITXOR(Sheet2!$F$3,165)*256+_xlfn.BITXOR(Sheet2!$F$4,165)*65536+_xlfn.BITXOR(Sheet2!$F$5,165)*16777216 -> 1701654643 | AZ8: =_xlfn.BITXOR(Sheet2!$F$6,165)+_xlfn.BITXOR(Sheet2!$F$7,165)*256+_xlfn.BITXOR(Sheet2!$F$8,165)*65536+_xlfn.BITXOR(Sheet2!$F$9,165)*16777216 -> 862876511 | BA8: =_xlfn.BITXOR(Sheet2!$F$10,165)+_xlfn.BITXOR(Sheet2!$F$11,165)*256+_xlfn.BITXOR(Sheet2!$F$12,165)*65536+_xlfn.BITXOR(Sheet2!$F$13,165)*16777216 -> 1601792820 | BB8: =_xlfn.BITXOR(Sheet2!$F$14,165)+_xlfn.BITXOR(Sheet2!$F$15,165)*256+_xlfn.BITXOR(Sheet2!$F$16,165)*65536+_xlfn.BITXOR(Sheet2!$F$17,165)*16777216 -> 1953248371 | BC8: =C8+D8*256+E8*65536+F8*16777216 -> 2151628607 | BD8: =G8+H8*256+I8*65536+J8*16777216 -> 0 | BE8: =K8+L8*256+M8*65536+N8*16777216 -> 0 | BF8: =O8+P8*256+Q8*65536+R8*16777216 -> 0 | BG8: =S8+T8*256+U8*65536+V8*16777216 -> 0 | BH8: =W8+X8*256+Y8*65536+Z8*16777216 -> 0 | BI8: =AA8+AB8*256+AC8*65536+AD8*16777216 -> 0 | BJ8: =AE8+AF8*256+AG8*65536+AH8*16777216 -> 0 | BK8: =AI8+AJ8*256+AK8*65536+AL8*16777216 -> 0 | BL8: =AM8+AN8*256+AO8*65536+AP8*16777216 -> 0 | BM8: =AQ8+AR8*256+AS8*65536+AT8*16777216 -> 152 | BN8: =AU8+AV8*256+AW8*65536+AX8*16777216 -> 0 | BO8: =MOD(1732584193+Sheet4!$J$456,4294967296) -> 2864597674 | BP8: =MOD(4023233417+Sheet4!$K$456,4294967296) -> 3283020593 | BQ8: =MOD(2562383102+Sheet4!$L$456,4294967296) -> 3317144422 | BR8: =MOD(271733878+Sheet4!$M$456,4294967296) -> 2031522474 | BS8: 3409560921 | BT8: 3103012121 | BU8: 2261944769 | BV8: 3919384297 | BW8: =IF(AND(BO8=BS8,BP8=BT8,BQ8=BU8,BR8=BV8),1,0) -> 0
A9: 8 | B9: =COUNT(Sheet2!$F$2:$F$17)+COUNT($C9:$E9) -> 19 | C9: =CODE(MID(Sheet2!$H$2,$A9,1)) -> 63 | D9: =CODE(MID(Sheet2!$H$2,$A9+10,1)) -> 63 | E9: =CODE(MID(Sheet2!$H$2,$A9+20,1)) -> 63 | F9: 128 | G9: 0 | H9: 0 | I9: 0 | J9: 0 | K9: 0 | L9: 0 | M9: 0 | N9: 0 | O9: 0 | P9: 0 | Q9: 0 | R9: 0 | S9: 0 | T9: 0 | U9: 0 | V9: 0 | W9: 0 | X9: 0 | Y9: 0 | Z9: 0 | AA9: 0 | AB9: 0 | AC9: 0 | AD9: 0 | AE9: 0 | AF9: 0 | AG9: 0 | AH9: 0 | AI9: 0 | AJ9: 0 | AK9: 0 | AL9: 0 | AM9: 0 | AN9: 0 | AO9: 0 | AP9: 0 | AQ9: =MOD(INT($B9*8/256^0),256) -> 152 | AR9: =MOD(INT($B9*8/256^1),256) -> 0 | AS9: =MOD(INT($B9*8/256^2),256) -> 0 | AT9: =MOD(INT($B9*8/256^3),256) -> 0 | AU9: =MOD(INT($B9*8/256^4),256) -> 0 | AV9: =MOD(INT($B9*8/256^5),256) -> 0 | AW9: =MOD(INT($B9*8/256^6),256) -> 0 | AX9: =MOD(INT($B9*8/256^7),256) -> 0 | AY9: =_xlfn.BITXOR(Sheet2!$F$2,165)+_xlfn.BITXOR(Sheet2!$F$3,165)*256+_xlfn.BITXOR(Sheet2!$F$4,165)*65536+_xlfn.BITXOR(Sheet2!$F$5,165)*16777216 -> 1701654643 | AZ9: =_xlfn.BITXOR(Sheet2!$F$6,165)+_xlfn.BITXOR(Sheet2!$F$7,165)*256+_xlfn.BITXOR(Sheet2!$F$8,165)*65536+_xlfn.BITXOR(Sheet2!$F$9,165)*16777216 -> 862876511 | BA9: =_xlfn.BITXOR(Sheet2!$F$10,165)+_xlfn.BITXOR(Sheet2!$F$11,165)*256+_xlfn.BITXOR(Sheet2!$F$12,165)*65536+_xlfn.BITXOR(Sheet2!$F$13,165)*16777216 -> 1601792820 | BB9: =_xlfn.BITXOR(Sheet2!$F$14,165)+_xlfn.BITXOR(Sheet2!$F$15,165)*256+_xlfn.BITXOR(Sheet2!$F$16,165)*65536+_xlfn.BITXOR(Sheet2!$F$17,165)*16777216 -> 1953248371 | BC9: =C9+D9*256+E9*65536+F9*16777216 -> 2151628607 | BD9: =G9+H9*256+I9*65536+J9*16777216 -> 0 | BE9: =K9+L9*256+M9*65536+N9*16777216 -> 0 | BF9: =O9+P9*256+Q9*65536+R9*16777216 -> 0 | BG9: =S9+T9*256+U9*65536+V9*16777216 -> 0 | BH9: =W9+X9*256+Y9*65536+Z9*16777216 -> 0 | BI9: =AA9+AB9*256+AC9*65536+AD9*16777216 -> 0 | BJ9: =AE9+AF9*256+AG9*65536+AH9*16777216 -> 0 | BK9: =AI9+AJ9*256+AK9*65536+AL9*16777216 -> 0 | BL9: =AM9+AN9*256+AO9*65536+AP9*16777216 -> 0 | BM9: =AQ9+AR9*256+AS9*65536+AT9*16777216 -> 152 | BN9: =AU9+AV9*256+AW9*65536+AX9*16777216 -> 0 | BO9: =MOD(1732584193+Sheet4!$J$521,4294967296) -> 2864597674 | BP9: =MOD(4023233417+Sheet4!$K$521,4294967296) -> 3283020593 | BQ9: =MOD(2562383102+Sheet4!$L$521,4294967296) -> 3317144422 | BR9: =MOD(271733878+Sheet4!$M$521,4294967296) -> 2031522474 | BS9: 3377601125 | BT9: 847392938 | BU9: 543800179 | BV9: 879909070 | BW9: =IF(AND(BO9=BS9,BP9=BT9,BQ9=BU9,BR9=BV9),1,0) -> 0
A10: 9 | B10: =COUNT(Sheet2!$F$2:$F$17)+COUNT($C10:$E10) -> 19 | C10: =CODE(MID(Sheet2!$H$2,$A10,1)) -> 63 | D10: =CODE(MID(Sheet2!$H$2,$A10+10,1)) -> 63 | E10: =CODE(MID(Sheet2!$H$2,$A10+20,1)) -> 63 | F10: 128 | G10: 0 | H10: 0 | I10: 0 | J10: 0 | K10: 0 | L10: 0 | M10: 0 | N10: 0 | O10: 0 | P10: 0 | Q10: 0 | R10: 0 | S10: 0 | T10: 0 | U10: 0 | V10: 0 | W10: 0 | X10: 0 | Y10: 0 | Z10: 0 | AA10: 0 | AB10: 0 | AC10: 0 | AD10: 0 | AE10: 0 | AF10: 0 | AG10: 0 | AH10: 0 | AI10: 0 | AJ10: 0 | AK10: 0 | AL10: 0 | AM10: 0 | AN10: 0 | AO10: 0 | AP10: 0 | AQ10: =MOD(INT($B10*8/256^0),256) -> 152 | AR10: =MOD(INT($B10*8/256^1),256) -> 0 | AS10: =MOD(INT($B10*8/256^2),256) -> 0 | AT10: =MOD(INT($B10*8/256^3),256) -> 0 | AU10: =MOD(INT($B10*8/256^4),256) -> 0 | AV10: =MOD(INT($B10*8/256^5),256) -> 0 | AW10: =MOD(INT($B10*8/256^6),256) -> 0 | AX10: =MOD(INT($B10*8/256^7),256) -> 0 | AY10: =_xlfn.BITXOR(Sheet2!$F$2,165)+_xlfn.BITXOR(Sheet2!$F$3,165)*256+_xlfn.BITXOR(Sheet2!$F$4,165)*65536+_xlfn.BITXOR(Sheet2!$F$5,165)*16777216 -> 1701654643 | AZ10: =_xlfn.BITXOR(Sheet2!$F$6,165)+_xlfn.BITXOR(Sheet2!$F$7,165)*256+_xlfn.BITXOR(Sheet2!$F$8,165)*65536+_xlfn.BITXOR(Sheet2!$F$9,165)*16777216 -> 862876511 | BA10: =_xlfn.BITXOR(Sheet2!$F$10,165)+_xlfn.BITXOR(Sheet2!$F$11,165)*256+_xlfn.BITXOR(Sheet2!$F$12,165)*65536+_xlfn.BITXOR(Sheet2!$F$13,165)*16777216 -> 1601792820 | BB10: =_xlfn.BITXOR(Sheet2!$F$14,165)+_xlfn.BITXOR(Sheet2!$F$15,165)*256+_xlfn.BITXOR(Sheet2!$F$16,165)*65536+_xlfn.BITXOR(Sheet2!$F$17,165)*16777216 -> 1953248371 | BC10: =C10+D10*256+E10*65536+F10*16777216 -> 2151628607 | BD10: =G10+H10*256+I10*65536+J10*16777216 -> 0 | BE10: =K10+L10*256+M10*65536+N10*16777216 -> 0 | BF10: =O10+P10*256+Q10*65536+R10*16777216 -> 0 | BG10: =S10+T10*256+U10*65536+V10*16777216 -> 0 | BH10: =W10+X10*256+Y10*65536+Z10*16777216 -> 0 | BI10: =AA10+AB10*256+AC10*65536+AD10*16777216 -> 0 | BJ10: =AE10+AF10*256+AG10*65536+AH10*16777216 -> 0 | BK10: =AI10+AJ10*256+AK10*65536+AL10*16777216 -> 0 | BL10: =AM10+AN10*256+AO10*65536+AP10*16777216 -> 0 | BM10: =AQ10+AR10*256+AS10*65536+AT10*16777216 -> 152 | BN10: =AU10+AV10*256+AW10*65536+AX10*16777216 -> 0 | BO10: =MOD(1732584193+Sheet4!$J$586,4294967296) -> 2864597674 | BP10: =MOD(4023233417+Sheet4!$K$586,4294967296) -> 3283020593 | BQ10: =MOD(2562383102+Sheet4!$L$586,4294967296) -> 3317144422 | BR10: =MOD(271733878+Sheet4!$M$586,4294967296) -> 2031522474 | BS10: 2343965920 | BT10: 2169933120 | BU10: 1366115365 | BV10: 931825985 | BW10: =IF(AND(BO10=BS10,BP10=BT10,BQ10=BU10,BR10=BV10),1,0) -> 0
A11: 10 | B11: =COUNT(Sheet2!$F$2:$F$17)+COUNT($C11:$E11) -> 19 | C11: =CODE(MID(Sheet2!$H$2,$A11,1)) -> 63 | D11: =CODE(MID(Sheet2!$H$2,$A11+10,1)) -> 63 | E11: =CODE(MID(Sheet2!$H$2,$A11+20,1)) -> 63 | F11: 128 | G11: 0 | H11: 0 | I11: 0 | J11: 0 | K11: 0 | L11: 0 | M11: 0 | N11: 0 | O11: 0 | P11: 0 | Q11: 0 | R11: 0 | S11: 0 | T11: 0 | U11: 0 | V11: 0 | W11: 0 | X11: 0 | Y11: 0 | Z11: 0 | AA11: 0 | AB11: 0 | AC11: 0 | AD11: 0 | AE11: 0 | AF11: 0 | AG11: 0 | AH11: 0 | AI11: 0 | AJ11: 0 | AK11: 0 | AL11: 0 | AM11: 0 | AN11: 0 | AO11: 0 | AP11: 0 | AQ11: =MOD(INT($B11*8/256^0),256) -> 152 | AR11: =MOD(INT($B11*8/256^1),256) -> 0 | AS11: =MOD(INT($B11*8/256^2),256) -> 0 | AT11: =MOD(INT($B11*8/256^3),256) -> 0 | AU11: =MOD(INT($B11*8/256^4),256) -> 0 | AV11: =MOD(INT($B11*8/256^5),256) -> 0 | AW11: =MOD(INT($B11*8/256^6),256) -> 0 | AX11: =MOD(INT($B11*8/256^7),256) -> 0 | AY11: =_xlfn.BITXOR(Sheet2!$F$2,165)+_xlfn.BITXOR(Sheet2!$F$3,165)*256+_xlfn.BITXOR(Sheet2!$F$4,165)*65536+_xlfn.BITXOR(Sheet2!$F$5,165)*16777216 -> 1701654643 | AZ11: =_xlfn.BITXOR(Sheet2!$F$6,165)+_xlfn.BITXOR(Sheet2!$F$7,165)*256+_xlfn.BITXOR(Sheet2!$F$8,165)*65536+_xlfn.BITXOR(Sheet2!$F$9,165)*16777216 -> 862876511 | BA11: =_xlfn.BITXOR(Sheet2!$F$10,165)+_xlfn.BITXOR(Sheet2!$F$11,165)*256+_xlfn.BITXOR(Sheet2!$F$12,165)*65536+_xlfn.BITXOR(Sheet2!$F$13,165)*16777216 -> 1601792820 | BB11: =_xlfn.BITXOR(Sheet2!$F$14,165)+_xlfn.BITXOR(Sheet2!$F$15,165)*256+_xlfn.BITXOR(Sheet2!$F$16,165)*65536+_xlfn.BITXOR(Sheet2!$F$17,165)*16777216 -> 1953248371 | BC11: =C11+D11*256+E11*65536+F11*16777216 -> 2151628607 | BD11: =G11+H11*256+I11*65536+J11*16777216 -> 0 | BE11: =K11+L11*256+M11*65536+N11*16777216 -> 0 | BF11: =O11+P11*256+Q11*65536+R11*16777216 -> 0 | BG11: =S11+T11*256+U11*65536+V11*16777216 -> 0 | BH11: =W11+X11*256+Y11*65536+Z11*16777216 -> 0 | BI11: =AA11+AB11*256+AC11*65536+AD11*16777216 -> 0 | BJ11: =AE11+AF11*256+AG11*65536+AH11*16777216 -> 0 | BK11: =AI11+AJ11*256+AK11*65536+AL11*16777216 -> 0 | BL11: =AM11+AN11*256+AO11*65536+AP11*16777216 -> 0 | BM11: =AQ11+AR11*256+AS11*65536+AT11*16777216 -> 152 | BN11: =AU11+AV11*256+AW11*65536+AX11*16777216 -> 0 | BO11: =MOD(1732584193+Sheet4!$J$651,4294967296) -> 2864597674 | BP11: =MOD(4023233417+Sheet4!$K$651,4294967296) -> 3283020593 | BQ11: =MOD(2562383102+Sheet4!$L$651,4294967296) -> 3317144422 | BR11: =MOD(271733878+Sheet4!$M$651,4294967296) -> 2031522474 | BS11: 1416552657 | BT11: 3925964814 | BU11: 413409308 | BV11: 1810266362 | BW11: =IF(AND(BO11=BS11,BP11=BT11,BQ11=BU11,BR11=BV11),1,0) -> 0

Sheet Sheet4
A1: c1 | B1: c2 | C1: c3 | D1: c4 | E1: c5 | F1: c6 | G1: c7 | H1: c8 | I1: c9 | J1: c10 | K1: c11 | L1: c12 | M1: c13
A2: 1 | B2: -1 | J2: 1732584193 | K2: 4023233417 | L2: 2562383102 | M2: 271733878
A3: 1 | B3: 0 | C3: =INDEX(Sheet2!$B$2:$B$65,$B3+1) -> 3614090360 | D3: =INDEX(Sheet2!$C$2:$C$65,$B3+1) -> 7 | E3: =INDEX(Sheet2!$D$2:$D$65,$B3+1) -> 0 | F3: =INDEX(Sheet3!$AY$2:$BN$11,$A3,$E3+1) -> 1701654643 | G3: =IF($B3<16,_xlfn.BITOR(_xlfn.BITAND($K2,$L2),_xlfn.BITAND(4294967295-$K2,$M2)),IF($B3<32,_xlfn.BITOR(_xlfn.BITAND($M2,$K2),_xlfn.BITAND(4294967295-$M2,$L2)),IF($B3<48,_xlfn.BITXOR(_xlfn.BITXOR($K2,$L2),$M2),_xlfn.BITXOR($L2,_xlfn.BITOR($K2,4294967295-$M2))))) -> 2562383102 | H3: =MOD($G3+$J2+$C3+$F3,4294967296) -> 1020777706 | I3: =MOD($H3,2^(32-$D3))*2^$D3+INT($H3/2^(32-$D3)) -> 1810527518 | J3: =$M2 -> 271733878 | K3: =MOD($K2+$I3,4294967296) -> 1538793639 | L3: =$K2 -> 4023233417 | M3: =$L2 -> 2562383102
A4: 1 | B4: 1 | C4: =INDEX(Sheet2!$B$2:$B$65,$B4+1) -> 3905402710 | D4: =INDEX(Sheet2!$C$2:$C$65,$B4+1) -> 12 | E4: =INDEX(Sheet2!$D$2:$D$65,$B4+1) -> 1 | F4: =INDEX(Sheet3!$AY$2:$BN$11,$A4,$E4+1) -> 862876511 | G4: =IF($B4<16,_xlfn.BITOR(_xlfn.BITAND($K3,$L3),_xlfn.BITAND(4294967295-$K3,$M3)),IF($B4<32,_xlfn.BITOR(_xlfn.BITAND($M3,$K3),_xlfn.BITAND(4294967295-$M3,$L3)),IF($B4<48,_xlfn.BITXOR(_xlfn.BITXOR($K3,$L3),$M3),_xlfn.BITXOR($L3,_xlfn.BITOR($K3,4294967295-$M3))))) -> 3414883545 | H4: =MOD($G4+$J3+$C4+$F4,4294967296) -> 4159929348 | I4: =MOD($H4,2^(32-$D4))*2^$D4+INT($H4/2^(32-$D4)) -> 935350143 | J4: =$M3 -> 2562383102 | K4: =MOD($K3+$I4,4294967296) -> 2474143782 | L4: =$K3 -> 1538793639 | M4: =$L3 -> 4023233417
A5: 1 | B5: 2 | C5: =INDEX(Sheet2!$B$2:$B$65,$B5+1) -> 606105819 | D5: =INDEX(Sheet2!$C$2:$C$65,$B5+1) -> 17 | E5: =INDEX(Sheet2!$D$2:$D$65,$B5+1) -> 2 | F5: =INDEX(Sheet3!$AY$2:$BN$11,$A5,$E5+1) -> 1601792820 | G5: =IF($B5<16,_xlfn.BITOR(_xlfn.BITAND($K4,$L4),_xlfn.BITAND(4294967295-$K4,$M4)),IF($B5<32,_xlfn.BITOR(_xlfn.BITAND($M4,$K4),_xlfn.BITAND(4294967295-$M4,$L4)),IF($B5<48,_xlfn.BITXOR(_xlfn.BITXOR($K4,$L4),$M4),_xlfn.BITXOR($L4,_xlfn.BITOR($K4,4294967295-$M4))))) -> 2143136687 | H5: =MOD($G5+$J4+$C5+$F5,4294967296) -> 2618451132 | I5: =MOD($H5,2^(32-$D5))*2^$D5+INT($H5/2^(32-$D5)) -> 3380164644 | J5: =$M4 -> 4023233417 | K5: =MOD($K4+$I5,4294967296) -> 1559341130 | L5: =$K4 -> 2474143782 | M5: =$L4 -> 1538793639
A6: 1 | B6: 3 | C6: =INDEX(Sheet2!$B$2:$B$65,$B6+1) -> 3250441966 | D6: =INDEX(Sheet2!$C$2:$C$65,$B6+1) -> 22 | E6: =INDEX(Sheet2!$D$2:$D$65,$B6+1) -> 3 | F6: =INDEX(Sheet3!$AY$2:$BN$11,$A6,$E6+1) -> 1953248371 | G6: =IF($B6<16,_xlfn.BITOR(_xlfn.BITAND($K5,$L5),_xlfn.BITAND(4294967295-$K5,$M5)),IF($B6<32,_xlfn.BITOR(_xlfn.BITAND($M5,$K5),_xlfn.BITAND(4294967295-$M5,$L5)),IF($B6<48,_xlfn.BITXOR(_xlfn.BITXOR($K5,$L5),$M5),_xlfn.BITXOR($L5,_xlfn.BITOR($K5,4294967295-$M5))))) -> 326639783 | H6: =MOD($G6+$J5+$C6+$F6,4294967296) -> 963628945 | I6: =MOD($H6,2^(32-$D6))*2^$D6+INT($H6/2^(32-$D6)) -> 3830340595 | J6: =$M5 -> 1538793639 | K6: =MOD($K5+$I6,4294967296) -> 1094714429 | L6: =$K5 -> 1559341130 | M6: =$L5 -> 2474143782
A7: 1 | B7: 4 | C7: =INDEX(Sheet2!$B$2:$B$65,$B7+1) -> 4118548399 | D7: =INDEX(Sheet2!$C$2:$C$65,$B7+1) -> 7 | E7: =INDEX(Sheet2!$D$2:$D$65,$B7+1) -> 4 | F7: =INDEX(Sheet3!$AY$2:$BN$11,$A7,$E7+1) -> 2151628607 | G7: =IF($B7<16,_xlfn.BITOR(_xlfn.BITAND($K6,$L6),_xlfn.BITAND(4294967295-$K6,$M6)),IF($B7<32,_xlfn.BITOR(_xlfn.BITAND($M6,$K6),_xlfn.BITAND(4294967295-$M6,$L6)),IF($B7<48,_xlfn.BITXOR(_xlfn.BITXOR($K6,$L6),$M6),_xlfn.BITXOR($L6,_xlfn.BITOR($K6,4294967295-$M6))))) -> 3531108362 | H7: =MOD($G7+$J6+$C7+$F7,4294967296) -> 2750144415 | I7: =MOD($H7,2^(32-$D7))*2^$D7+INT($H7/2^(32-$D7)) -> 4126134225 | J7: =$M6 -> 2474143782 | K7: =MOD($K6+$I7,4294967296) -> 925881358 | L7: =$K6 -> 1094714429 | M7: =$L6 -> 1559341130
A8: 1 | B8: 5 | C8: =INDEX(Sheet2!$B$2:$B$65,$B8+1) -> 1200080426 | D8: =INDEX(Sheet2!$C$2:$C$65,$B8+1) -> 12 | E8: =INDEX(Sheet2!$D$2:$D$65,$B8+1) -> 5 | F8: =INDEX(Sheet3!$AY$2:$BN$11,$A8,$E8+1) -> 0 | G8: =IF($B8<16,_xlfn.BITOR(_xlfn.BITAND($K7,$L7),_xlfn.BITAND(4294967295-$K7,$M7)),IF($B8<32,_xlfn.BITOR(_xlfn.BITAND($M7,$K7),_xlfn.BITAND(4294967295-$M7,$L7)),IF($B8<48,_xlfn.BITXOR(_xlfn.BITXOR($K7,$L7),$M7),_xlfn.BITXOR($L7,_xlfn.BITOR($K7,4294967295-$M7))))) -> 1238379596 | H8: =MOD($G8+$J7+$C8+$F8,4294967296) -> 617636508 | I8: =MOD($H8,2^(32-$D8))*2^$D8+INT($H8/2^(32-$D8)) -> 103400013 | J8: =$M7 -> 1559341130 | K8: =MOD($K7+$I8,4294967296) -> 1029281371 | L8: =$K7 -> 925881358 | M8: =$L7 -> 1094714429
A9: 1 | B9: 6 | C9: =INDEX(Sheet2!$B$2:$B$65,$B9+1) -> 2821735955 | D9: =INDEX(Sheet2!$C$2:$C$65,$B9+1) -> 17 | E9: =INDEX(Sheet2!$D$2:$D$65,$B9+1) -> 6 | F9: =INDEX(Sheet3!$AY$2:$BN$11,$A9,$E9+1) -> 0 | G9: =IF($B9<16,_xlfn.BITOR(_xlfn.BITAND($K8,$L8),_xlfn.BITAND(4294967295-$K8,$M8)),IF($B9<32,_xlfn.BITOR(_xlfn.BITAND($M8,$K8),_xlfn.BITAND(4294967295-$M8,$L8)),IF($B9<48,_xlfn.BITXOR(_xlfn.BITXOR($K8,$L8),$M8),_xlfn.BITXOR($L8,_xlfn.BITOR($K8,4294967295-$M8))))) -> 1963562030 | H9: =MOD($G9+$J8+$C9+$F9,4294967296) -> 2049671819 | I9: =MOD($H9,2^(32-$D9))*2^$D9+INT($H9/2^(32-$D9)) -> 85390423 | J9: =$M8 -> 1094714429 | K9: =MOD($K8+$I9,4294967296) -> 1114671794 | L9: =$K8 -> 1029281371 | M9: =$L8 -> 925881358
A10: 1 | B10: 7 | C10: =INDEX(Sheet2!$B$2:$B$65,$B10+1) -> 4249261313 | D10: =INDEX(Sheet2!$C$2:$C$65,$B10+1) -> 22 | E10: =INDEX(Sheet2!$D$2:$D$65,$B10+1) -> 7 | F10: =INDEX(Sheet3!$AY$2:$BN$11,$A10,$E10+1) -> 0 | G10: =IF($B10<16,_xlfn.BITOR(_xlfn.BITAND($K9,$L9),_xlfn.BITAND(4294967295-$K9,$M9)),IF($B10<32,_xlfn.BITOR(_xlfn.BITAND($M9,$K9),_xlfn.BITAND(4294967295-$M9,$L9)),IF($B10<48,_xlfn.BITXOR(_xlfn.BITXOR($K9,$L9),$M9),_xlfn.BITXOR($L9,_xlfn.BITOR($K9,4294967295-$M9))))) -> 895473182 | H10: =MOD($G10+$J9+$C10+$F10,4294967296) -> 1944481628 | I10: =MOD($H10,2^(32-$D10))*2^$D10+INT($H10/2^(32-$D10)) -> 3609000347 | J10: =$M9 -> 925881358 | K10: =MOD($K9+$I10,4294967296) -> 428704845 | L10: =$K9 -> 1114671794 | M10: =$L9 -> 1029281371
A11: 1 | B11: 8 | C11: =INDEX(Sheet2!$B$2:$B$65,$B11+1) -> 1770035416 | D11: =INDEX(Sheet2!$C$2:$C$65,$B11+1) -> 7 | E11: =INDEX(Sheet2!$D$2:$D$65,$B11+1) -> 8 | F11: =INDEX(Sheet3!$AY$2:$BN$11,$A11,$E11+1) -> 0 | G11: =IF($B11<16,_xlfn.BITOR(_xlfn.BITAND($K10,$L10),_xlfn.BITAND(4294967295-$K10,$M10)),IF($B11<32,_xlfn.BITOR(_xlfn.BITAND($M10,$K10),_xlfn.BITAND(4294967295-$M10,$L10)),IF($B11<48,_xlfn.BITXOR(_xlfn.BITXOR($K10,$L10),$M10),_xlfn.BITXOR($L10,_xlfn.BITOR($K10,4294967295-$M10))))) -> 609260050 | H11: =MOD($G11+$J10+$C11+$F11,4294967296) -> 3305176824 | I11: =MOD($H11,2^(32-$D11))*2^$D11+INT($H11/2^(32-$D11)) -> 2155838562 | J11: =$M10 -> 1029281371 | K11: =MOD($K10+$I11,4294967296) -> 2584543407 | L11: =$K10 -> 428704845 | M11: =$L10 -> 1114671794
A12: 1 | B12: 9 | C12: =INDEX(Sheet2!$B$2:$B$65,$B12+1) -> 2336552879 | D12: =INDEX(Sheet2!$C$2:$C$65,$B12+1) -> 12 | E12: =INDEX(Sheet2!$D$2:$D$65,$B12+1) -> 9 | F12: =INDEX(Sheet3!$AY$2:$BN$11,$A12,$E12+1) -> 0 | G12: =IF($B12<16,_xlfn.BITOR(_xlfn.BITAND($K11,$L11),_xlfn.BITAND(4294967295-$K11,$M11)),IF($B12<32,_xlfn.BITOR(_xlfn.BITAND($M11,$K11),_xlfn.BITAND(4294967295-$M11,$L11)),IF($B12<48,_xlfn.BITXOR(_xlfn.BITXOR($K11,$L11),$M11),_xlfn.BITXOR($L11,_xlfn.BITOR($K11,4294967295-$M11))))) -> 1484622365 | H12: =MOD($G12+$J11+$C12+$F12,4294967296) -> 555489319 | I12: =MOD($H12,2^(32-$D12))*2^$D12+INT($H12/2^(32-$D12)) -> 3246551569 | J12: =$M11 -> 1114671794 | K12: =MOD($K11+$I12,4294967296) -> 1536127680 | L12: =$K11 -> 2584543407 | M12: =$L11 -> 428704845
A13: 1 | B13: 10 | C13: =INDEX(Sheet2!$B$2:$B$65,$B13+1) -> 4294925233 | D13: =INDEX(Sheet2!$C$2:$C$65,$B13+1) -> 17 | E13: =INDEX(Sheet2!$D$2:$D$65,$B13+1) -> 10 | F13: =INDEX(Sheet3!$AY$2:$BN$11,$A13,$E13+1) -> 0 | G13: =IF($B13<16,_xlfn.BITOR(_xlfn.BITAND($K12,$L12),_xlfn.BITAND(4294967295-$K12,$M12)),IF($B13<32,_xlfn.BITOR(_xlfn.BITAND($M12,$K12),_xlfn.BITAND(4294967295-$M12,$L12)),IF($B13<48,_xlfn.BITXOR(_xlfn.BITXOR($K12,$L12),$M12),_xlfn.BITXOR($L12,_xlfn.BITOR($K12,4294967295-$M12))))) -> 437093517 | H13: =MOD($G13+$J12+$C13+$F13,4294967296) -> 1551723248 | I13: =MOD($H13,2^(32-$D13))*2^$D13+INT($H13/2^(32-$D13)) -> 3588274426 | J13: =$M12 -> 428704845 | K13: =MOD($K12+$I13,4294967296) -> 829434810 | L13: =$K12 -> 1536127680 | M13: =$L12 -> 2584543407
A14: 1 | B14: 11 | C14: =INDEX(Sheet2!$B$2:$B$65,$B14+1) -> 2304563134 | D14: =INDEX(Sheet2!$C$2:$C$65,$B14+1) -> 22 | E14: =INDEX(Sheet2!$D$2:$D$65,$B14+1) -> 11 | F14: =INDEX(Sheet3!$AY$2:$BN$11,$A14,$E14+1) -> 0 | G14: =IF($B14<16,_xlfn.BITOR(_xlfn.BITAND($K13,$L13),_xlfn.BITAND(4294967295-$K13,$M13)),IF($B14<32,_xlfn.BITOR(_xlfn.BITAND($M13,$K13),_xlfn.BITAND(4294967295-$M13,$L13)),IF($B14<48,_xlfn.BITXOR(_xlfn.BITXOR($K13,$L13),$M13),_xlfn.BITXOR($L13,_xlfn.BITOR($K13,4294967295-$M13))))) -> 2601329285 | H14: =MOD($G14+$J13+$C14+$F14,4294967296) -> 1039629968 | I14: =MOD($H14,2^(32-$D14))*2^$D14+INT($H14/2^(32-$D14)) -> 2752478687 | J14: =$M13 -> 2584543407 | K14: =MOD($K13+$I14,4294967296) -> 3581913497 | L14: =$K13 -> 829434810 | M14: =$L13 -> 1536127680
... A66: 1 | B66: 63 | C66: =INDEX(Sheet2!$B$2:$B$65,$B66+1) -> 3951481745 | D66: =INDEX(Sheet2!$C$2:$C$65,$B66+1) -> 21 | E66: =INDEX(Sheet2!$D$2:$D$65,$B66+1) -> 9 | F66: =INDEX(Sheet3!$AY$2:$BN$11,$A66,$E66+1) -> 0 | G66: =IF($B66<16,_xlfn.BITOR(_xlfn.BITAND($K65,$L65),_xlfn.BITAND(4294967295-$K65,$M65)),IF($B66<32,_xlfn.BITOR(_xlfn.BITAND($M65,$K65),_xlfn.BITAND(4294967295-$M65,$L65)),IF($B66<48,_xlfn.BITXOR(_xlfn.BITXOR($K65,$L65),$M65),_xlfn.BITXOR($L65,_xlfn.BITOR($K65,4294967295-$M65))))) -> 3558522954 | H66: =MOD($G66+$J65+$C66+$F66,4294967296) -> 604636471 | I66: =MOD($H66,2^(32-$D66))*2^$D66+INT($H66/2^(32-$D66)) -> 2799993152 | J66: =$M65 -> 1132013481 | K66: =MOD($K65+$I66,4294967296) -> 3554754472 | L66: =$K65 -> 754761320 | M66: =$L65 -> 1759788596
A67: 2 | B67: -1 | J67: 1732584193 | K67: 4023233417 | L67: 2562383102 | M67: 271733878
A68: 2 | B68: 0 | C68: =INDEX(Sheet2!$B$2:$B$65,$B68+1) -> 3614090360 | D68: =INDEX(Sheet2!$C$2:$C$65,$B68+1) -> 7 | E68: =INDEX(Sheet2!$D$2:$D$65,$B68+1) -> 0 | F68: =INDEX(Sheet3!$AY$2:$BN$11,$A68,$E68+1) -> 1701654643 | G68: =IF($B68<16,_xlfn.BITOR(_xlfn.BITAND($K67,$L67),_xlfn.BITAND(4294967295-$K67,$M67)),IF($B68<32,_xlfn.BITOR(_xlfn.BITAND($M67,$K67),_xlfn.BITAND(4294967295-$M67,$L67)),IF($B68<48,_xlfn.BITXOR(_xlfn.BITXOR($K67,$L67),$M67),_xlfn.BITXOR($L67,_xlfn.BITOR($K67,4294967295-$M67))))) -> 2562383102 | H68: =MOD($G68+$J67+$C68+$F68,4294967296) -> 1020777706 | I68: =MOD($H68,2^(32-$D68))*2^$D68+INT($H68/2^(32-$D68)) -> 1810527518 | J68: =$M67 -> 271733878 | K68: =MOD($K67+$I68,4294967296) -> 1538793639 | L68: =$K67 -> 4023233417 | M68: =$L67 -> 2562383102
A69: 2 | B69: 1 | C69: =INDEX(Sheet2!$B$2:$B$65,$B69+1) -> 3905402710 | D69: =INDEX(Sheet2!$C$2:$C$65,$B69+1) -> 12 | E69: =INDEX(Sheet2!$D$2:$D$65,$B69+1) -> 1 | F69: =INDEX(Sheet3!$AY$2:$BN$11,$A69,$E69+1) -> 862876511 | G69: =IF($B69<16,_xlfn.BITOR(_xlfn.BITAND($K68,$L68),_xlfn.BITAND(4294967295-$K68,$M68)),IF($B69<32,_xlfn.BITOR(_xlfn.BITAND($M68,$K68),_xlfn.BITAND(4294967295-$M68,$L68)),IF($B69<48,_xlfn.BITXOR(_xlfn.BITXOR($K68,$L68),$M68),_xlfn.BITXOR($L68,_xlfn.BITOR($K68,4294967295-$M68))))) -> 3414883545 | H69: =MOD($G69+$J68+$C69+$F69,4294967296) -> 4159929348 | I69: =MOD($H69,2^(32-$D69))*2^$D69+INT($H69/2^(32-$D69)) -> 935350143 | J69: =$M68 -> 2562383102 | K69: =MOD($K68+$I69,4294967296) -> 2474143782 | L69: =$K68 -> 1538793639 | M69: =$L68 -> 4023233417
A70: 2 | B70: 2 | C70: =INDEX(Sheet2!$B$2:$B$65,$B70+1) -> 606105819 | D70: =INDEX(Sheet2!$C$2:$C$65,$B70+1) -> 17 | E70: =INDEX(Sheet2!$D$2:$D$65,$B70+1) -> 2 | F70: =INDEX(Sheet3!$AY$2:$BN$11,$A70,$E70+1) -> 1601792820 | G70: =IF($B70<16,_xlfn.BITOR(_xlfn.BITAND($K69,$L69),_xlfn.BITAND(4294967295-$K69,$M69)),IF($B70<32,_xlfn.BITOR(_xlfn.BITAND($M69,$K69),_xlfn.BITAND(4294967295-$M69,$L69)),IF($B70<48,_xlfn.BITXOR(_xlfn.BITXOR($K69,$L69),$M69),_xlfn.BITXOR($L69,_xlfn.BITOR($K69,4294967295-$M69))))) -> 2143136687 | H70: =MOD($G70+$J69+$C70+$F70,4294967296) -> 2618451132 | I70: =MOD($H70,2^(32-$D70))*2^$D70+INT($H70/2^(32-$D70)) -> 3380164644 | J70: =$M69 -> 4023233417 | K70: =MOD($K69+$I70,4294967296) -> 1559341130 | L70: =$K69 -> 2474143782 | M70: =$L69 -> 1538793639
A71: 2 | B71: 3 | C71: =INDEX(Sheet2!$B$2:$B$65,$B71+1) -> 3250441966 | D71: =INDEX(Sheet2!$C$2:$C$65,$B71+1) -> 22 | E71: =INDEX(Sheet2!$D$2:$D$65,$B71+1) -> 3 | F71: =INDEX(Sheet3!$AY$2:$BN$11,$A71,$E71+1) -> 1953248371 | G71: =IF($B71<16,_xlfn.BITOR(_xlfn.BITAND($K70,$L70),_xlfn.BITAND(4294967295-$K70,$M70)),IF($B71<32,_xlfn.BITOR(_xlfn.BITAND($M70,$K70),_xlfn.BITAND(4294967295-$M70,$L70)),IF($B71<48,_xlfn.BITXOR(_xlfn.BITXOR($K70,$L70),$M70),_xlfn.BITXOR($L70,_xlfn.BITOR($K70,4294967295-$M70))))) -> 326639783 | H71: =MOD($G71+$J70+$C71+$F71,4294967296) -> 963628945 | I71: =MOD($H71,2^(32-$D71))*2^$D71+INT($H71/2^(32-$D71)) -> 3830340595 | J71: =$M70 -> 1538793639 | K71: =MOD($K70+$I71,4294967296) -> 1094714429 | L71: =$K70 -> 1559341130 | M71: =$L70 -> 2474143782
A72: 2 | B72: 4 | C72: =INDEX(Sheet2!$B$2:$B$65,$B72+1) -> 4118548399 | D72: =INDEX(Sheet2!$C$2:$C$65,$B72+1) -> 7 | E72: =INDEX(Sheet2!$D$2:$D$65,$B72+1) -> 4 | F72: =INDEX(Sheet3!$AY$2:$BN$11,$A72,$E72+1) -> 2151628607 | G72: =IF($B72<16,_xlfn.BITOR(_xlfn.BITAND($K71,$L71),_xlfn.BITAND(4294967295-$K71,$M71)),IF($B72<32,_xlfn.BITOR(_xlfn.BITAND($M71,$K71),_xlfn.BITAND(4294967295-$M71,$L71)),IF($B72<48,_xlfn.BITXOR(_xlfn.BITXOR($K71,$L71),$M71),_xlfn.BITXOR($L71,_xlfn.BITOR($K71,4294967295-$M71))))) -> 3531108362 | H72: =MOD($G72+$J71+$C72+$F72,4294967296) -> 2750144415 | I72: =MOD($H72,2^(32-$D72))*2^$D72+INT($H72/2^(32-$D72)) -> 4126134225 | J72: =$M71 -> 2474143782 | K72: =MOD($K71+$I72,4294967296) -> 925881358 | L72: =$K71 -> 1094714429 | M72: =$L71 -> 1559341130
A73: 2 | B73: 5 | C73: =INDEX(Sheet2!$B$2:$B$65,$B73+1) -> 1200080426 | D73: =INDEX(Sheet2!$C$2:$C$65,$B73+1) -> 12 | E73: =INDEX(Sheet2!$D$2:$D$65,$B73+1) -> 5 | F73: =INDEX(Sheet3!$AY$2:$BN$11,$A73,$E73+1) -> 0 | G73: =IF($B73<16,_xlfn.BITOR(_xlfn.BITAND($K72,$L72),_xlfn.BITAND(4294967295-$K72,$M72)),IF($B73<32,_xlfn.BITOR(_xlfn.BITAND($M72,$K72),_xlfn.BITAND(4294967295-$M72,$L72)),IF($B73<48,_xlfn.BITXOR(_xlfn.BITXOR($K72,$L72),$M72),_xlfn.BITXOR($L72,_xlfn.BITOR($K72,4294967295-$M72))))) -> 1238379596 | H73: =MOD($G73+$J72+$C73+$F73,4294967296) -> 617636508 | I73: =MOD($H73,2^(32-$D73))*2^$D73+INT($H73/2^(32-$D73)) -> 103400013 | J73: =$M72 -> 1559341130 | K73: =MOD($K72+$I73,4294967296) -> 1029281371 | L73: =$K72 -> 925881358 | M73: =$L72 -> 1094714429
A74: 2 | B74: 6 | C74: =INDEX(Sheet2!$B$2:$B$65,$B74+1) -> 2821735955 | D74: =INDEX(Sheet2!$C$2:$C$65,$B74+1) -> 17 | E74: =INDEX(Sheet2!$D$2:$D$65,$B74+1) -> 6 | F74: =INDEX(Sheet3!$AY$2:$BN$11,$A74,$E74+1) -> 0 | G74: =IF($B74<16,_xlfn.BITOR(_xlfn.BITAND($K73,$L73),_xlfn.BITAND(4294967295-$K73,$M73)),IF($B74<32,_xlfn.BITOR(_xlfn.BITAND($M73,$K73),_xlfn.BITAND(4294967295-$M73,$L73)),IF($B74<48,_xlfn.BITXOR(_xlfn.BITXOR($K73,$L73),$M73),_xlfn.BITXOR($L73,_xlfn.BITOR($K73,4294967295-$M73))))) -> 1963562030 | H74: =MOD($G74+$J73+$C74+$F74,4294967296) -> 2049671819 | I74: =MOD($H74,2^(32-$D74))*2^$D74+INT($H74/2^(32-$D74)) -> 85390423 | J74: =$M73 -> 1094714429 | K74: =MOD($K73+$I74,4294967296) -> 1114671794 | L74: =$K73 -> 1029281371 | M74: =$L73 -> 925881358
A75: 2 | B75: 7 | C75: =INDEX(Sheet2!$B$2:$B$65,$B75+1) -> 4249261313 | D75: =INDEX(Sheet2!$C$2:$C$65,$B75+1) -> 22 | E75: =INDEX(Sheet2!$D$2:$D$65,$B75+1) -> 7 | F75: =INDEX(Sheet3!$AY$2:$BN$11,$A75,$E75+1) -> 0 | G75: =IF($B75<16,_xlfn.BITOR(_xlfn.BITAND($K74,$L74),_xlfn.BITAND(4294967295-$K74,$M74)),IF($B75<32,_xlfn.BITOR(_xlfn.BITAND($M74,$K74),_xlfn.BITAND(4294967295-$M74,$L74)),IF($B75<48,_xlfn.BITXOR(_xlfn.BITXOR($K74,$L74),$M74),_xlfn.BITXOR($L74,_xlfn.BITOR($K74,4294967295-$M74))))) -> 895473182 | H75: =MOD($G75+$J74+$C75+$F75,4294967296) -> 1944481628 | I75: =MOD($H75,2^(32-$D75))*2^$D75+INT($H75/2^(32-$D75)) -> 3609000347 | J75: =$M74 -> 925881358 | K75: =MOD($K74+$I75,4294967296) -> 428704845 | L75: =$K74 -> 1114671794 | M75: =$L74 -> 1029281371
A76: 2 | B76: 8 | C76: =INDEX(Sheet2!$B$2:$B$65,$B76+1) -> 1770035416 | D76: =INDEX(Sheet2!$C$2:$C$65,$B76+1) -> 7 | E76: =INDEX(Sheet2!$D$2:$D$65,$B76+1) -> 8 | F76: =INDEX(Sheet3!$AY$2:$BN$11,$A76,$E76+1) -> 0 | G76: =IF($B76<16,_xlfn.BITOR(_xlfn.BITAND($K75,$L75),_xlfn.BITAND(4294967295-$K75,$M75)),IF($B76<32,_xlfn.BITOR(_xlfn.BITAND($M75,$K75),_xlfn.BITAND(4294967295-$M75,$L75)),IF($B76<48,_xlfn.BITXOR(_xlfn.BITXOR($K75,$L75),$M75),_xlfn.BITXOR($L75,_xlfn.BITOR($K75,4294967295-$M75))))) -> 609260050 | H76: =MOD($G76+$J75+$C76+$F76,4294967296) -> 3305176824 | I76: =MOD($H76,2^(32-$D76))*2^$D76+INT($H76/2^(32-$D76)) -> 2155838562 | J76: =$M75 -> 1029281371 | K76: =MOD($K75+$I76,4294967296) -> 2584543407 | L76: =$K75 -> 428704845 | M76: =$L75 -> 1114671794
A77: 2 | B77: 9 | C77: =INDEX(Sheet2!$B$2:$B$65,$B77+1) -> 2336552879 | D77: =INDEX(Sheet2!$C$2:$C$65,$B77+1) -> 12 | E77: =INDEX(Sheet2!$D$2:$D$65,$B77+1) -> 9 | F77: =INDEX(Sheet3!$AY$2:$BN$11,$A77,$E77+1) -> 0 | G77: =IF($B77<16,_xlfn.BITOR(_xlfn.BITAND($K76,$L76),_xlfn.BITAND(4294967295-$K76,$M76)),IF($B77<32,_xlfn.BITOR(_xlfn.BITAND($M76,$K76),_xlfn.BITAND(4294967295-$M76,$L76)),IF($B77<48,_xlfn.BITXOR(_xlfn.BITXOR($K76,$L76),$M76),_xlfn.BITXOR($L76,_xlfn.BITOR($K76,4294967295-$M76))))) -> 1484622365 | H77: =MOD($G77+$J76+$C77+$F77,4294967296) -> 555489319 | I77: =MOD($H77,2^(32-$D77))*2^$D77+INT($H77/2^(32-$D77)) -> 3246551569 | J77: =$M76 -> 1114671794 | K77: =MOD($K76+$I77,4294967296) -> 1536127680 | L77: =$K76 -> 2584543407 | M77: =$L76 -> 428704845
A78: 2 | B78: 10 | C78: =INDEX(Sheet2!$B$2:$B$65,$B78+1) -> 4294925233 | D78: =INDEX(Sheet2!$C$2:$C$65,$B78+1) -> 17 | E78: =INDEX(Sheet2!$D$2:$D$65,$B78+1) -> 10 | F78: =INDEX(Sheet3!$AY$2:$BN$11,$A78,$E78+1) -> 0 | G78: =IF($B78<16,_xlfn.BITOR(_xlfn.BITAND($K77,$L77),_xlfn.BITAND(4294967295-$K77,$M77)),IF($B78<32,_xlfn.BITOR(_xlfn.BITAND($M77,$K77),_xlfn.BITAND(4294967295-$M77,$L77)),IF($B78<48,_xlfn.BITXOR(_xlfn.BITXOR($K77,$L77),$M77),_xlfn.BITXOR($L77,_xlfn.BITOR($K77,4294967295-$M77))))) -> 437093517 | H78: =MOD($G78+$J77+$C78+$F78,4294967296) -> 1551723248 | I78: =MOD($H78,2^(32-$D78))*2^$D78+INT($H78/2^(32-$D78)) -> 3588274426 | J78: =$M77 -> 428704845 | K78: =MOD($K77+$I78,4294967296) -> 829434810 | L78: =$K77 -> 1536127680 | M78: =$L77 -> 2584543407
A79: 2 | B79: 11 | C79: =INDEX(Sheet2!$B$2:$B$65,$B79+1) -> 2304563134 | D79: =INDEX(Sheet2!$C$2:$C$65,$B79+1) -> 22 | E79: =INDEX(Sheet2!$D$2:$D$65,$B79+1) -> 11 | F79: =INDEX(Sheet3!$AY$2:$BN$11,$A79,$E79+1) -> 0 | G79: =IF($B79<16,_xlfn.BITOR(_xlfn.BITAND($K78,$L78),_xlfn.BITAND(4294967295-$K78,$M78)),IF($B79<32,_xlfn.BITOR(_xlfn.BITAND($M78,$K78),_xlfn.BITAND(4294967295-$M78,$L78)),IF($B79<48,_xlfn.BITXOR(_xlfn.BITXOR($K78,$L78),$M78),_xlfn.BITXOR($L78,_xlfn.BITOR($K78,4294967295-$M78))))) -> 2601329285 | H79: =MOD($G79+$J78+$C79+$F79,4294967296) -> 1039629968 | I79: =MOD($H79,2^(32-$D79))*2^$D79+INT($H79/2^(32-$D79)) -> 2752478687 | J79: =$M78 -> 2584543407 | K79: =MOD($K78+$I79,4294967296) -> 3581913497 | L79: =$K78 -> 829434810 | M79: =$L78 -> 1536127680
... A131: 2 | B131: 63 | C131: =INDEX(Sheet2!$B$2:$B$65,$B131+1) -> 3951481745 | D131: =INDEX(Sheet2!$C$2:$C$65,$B131+1) -> 21 | E131: =INDEX(Sheet2!$D$2:$D$65,$B131+1) -> 9 | F131: =INDEX(Sheet3!$AY$2:$BN$11,$A131,$E131+1) -> 0 | G131: =IF($B131<16,_xlfn.BITOR(_xlfn.BITAND($K130,$L130),_xlfn.BITAND(4294967295-$K130,$M130)),IF($B131<32,_xlfn.BITOR(_xlfn.BITAND($M130,$K130),_xlfn.BITAND(4294967295-$M130,$L130)),IF($B131<48,_xlfn.BITXOR(_xlfn.BITXOR($K130,$L130),$M130),_xlfn.BITXOR($L130,_xlfn.BITOR($K130,4294967295-$M130))))) -> 3558522954 | H131: =MOD($G131+$J130+$C131+$F131,4294967296) -> 604636471 | I131: =MOD($H131,2^(32-$D131))*2^$D131+INT($H131/2^(32-$D131)) -> 2799993152 | J131: =$M130 -> 1132013481 | K131: =MOD($K130+$I131,4294967296) -> 3554754472 | L131: =$K130 -> 754761320 | M131: =$L130 -> 1759788596
A132: 3 | B132: -1 | J132: 1732584193 | K132: 4023233417 | L132: 2562383102 | M132: 271733878
A133: 3 | B133: 0 | C133: =INDEX(Sheet2!$B$2:$B$65,$B133+1) -> 3614090360 | D133: =INDEX(Sheet2!$C$2:$C$65,$B133+1) -> 7 | E133: =INDEX(Sheet2!$D$2:$D$65,$B133+1) -> 0 | F133: =INDEX(Sheet3!$AY$2:$BN$11,$A133,$E133+1) -> 1701654643 | G133: =IF($B133<16,_xlfn.BITOR(_xlfn.BITAND($K132,$L132),_xlfn.BITAND(4294967295-$K132,$M132)),IF($B133<32,_xlfn.BITOR(_xlfn.BITAND($M132,$K132),_xlfn.BITAND(4294967295-$M132,$L132)),IF($B133<48,_xlfn.BITXOR(_xlfn.BITXOR($K132,$L132),$M132),_xlfn.BITXOR($L132,_xlfn.BITOR($K132,4294967295-$M132))))) -> 2562383102 | H133: =MOD($G133+$J132+$C133+$F133,4294967296) -> 1020777706 | I133: =MOD($H133,2^(32-$D133))*2^$D133+INT($H133/2^(32-$D133)) -> 1810527518 | J133: =$M132 -> 271733878 | K133: =MOD($K132+$I133,4294967296) -> 1538793639 | L133: =$K132 -> 4023233417 | M133: =$L132 -> 2562383102
A134: 3 | B134: 1 | C134: =INDEX(Sheet2!$B$2:$B$65,$B134+1) -> 3905402710 | D134: =INDEX(Sheet2!$C$2:$C$65,$B134+1) -> 12 | E134: =INDEX(Sheet2!$D$2:$D$65,$B134+1) -> 1 | F134: =INDEX(Sheet3!$AY$2:$BN$11,$A134,$E134+1) -> 862876511 | G134: =IF($B134<16,_xlfn.BITOR(_xlfn.BITAND($K133,$L133),_xlfn.BITAND(4294967295-$K133,$M133)),IF($B134<32,_xlfn.BITOR(_xlfn.BITAND($M133,$K133),_xlfn.BITAND(4294967295-$M133,$L133)),IF($B134<48,_xlfn.BITXOR(_xlfn.BITXOR($K133,$L133),$M133),_xlfn.BITXOR($L133,_xlfn.BITOR($K133,4294967295-$M133))))) -> 3414883545 | H134: =MOD($G134+$J133+$C134+$F134,4294967296) -> 4159929348 | I134: =MOD($H134,2^(32-$D134))*2^$D134+INT($H134/2^(32-$D134)) -> 935350143 | J134: =$M133 -> 2562383102 | K134: =MOD($K133+$I134,4294967296) -> 2474143782 | L134: =$K133 -> 1538793639 | M134: =$L133 -> 4023233417
A135: 3 | B135: 2 | C135: =INDEX(Sheet2!$B$2:$B$65,$B135+1) -> 606105819 | D135: =INDEX(Sheet2!$C$2:$C$65,$B135+1) -> 17 | E135: =INDEX(Sheet2!$D$2:$D$65,$B135+1) -> 2 | F135: =INDEX(Sheet3!$AY$2:$BN$11,$A135,$E135+1) -> 1601792820 | G135: =IF($B135<16,_xlfn.BITOR(_xlfn.BITAND($K134,$L134),_xlfn.BITAND(4294967295-$K134,$M134)),IF($B135<32,_xlfn.BITOR(_xlfn.BITAND($M134,$K134),_xlfn.BITAND(4294967295-$M134,$L134)),IF($B135<48,_xlfn.BITXOR(_xlfn.BITXOR($K134,$L134),$M134),_xlfn.BITXOR($L134,_xlfn.BITOR($K134,4294967295-$M134))))) -> 2143136687 | H135: =MOD($G135+$J134+$C135+$F135,4294967296) -> 2618451132 | I135: =MOD($H135,2^(32-$D135))*2^$D135+INT($H135/2^(32-$D135)) -> 3380164644 | J135: =$M134 -> 4023233417 | K135: =MOD($K134+$I135,4294967296) -> 1559341130 | L135: =$K134 -> 2474143782 | M135: =$L134 -> 1538793639
A136: 3 | B136: 3 | C136: =INDEX(Sheet2!$B$2:$B$65,$B136+1) -> 3250441966 | D136: =INDEX(Sheet2!$C$2:$C$65,$B136+1) -> 22 | E136: =INDEX(Sheet2!$D$2:$D$65,$B136+1) -> 3 | F136: =INDEX(Sheet3!$AY$2:$BN$11,$A136,$E136+1) -> 1953248371 | G136: =IF($B136<16,_xlfn.BITOR(_xlfn.BITAND($K135,$L135),_xlfn.BITAND(4294967295-$K135,$M135)),IF($B136<32,_xlfn.BITOR(_xlfn.BITAND($M135,$K135),_xlfn.BITAND(4294967295-$M135,$L135)),IF($B136<48,_xlfn.BITXOR(_xlfn.BITXOR($K135,$L135),$M135),_xlfn.BITXOR($L135,_xlfn.BITOR($K135,4294967295-$M135))))) -> 326639783 | H136: =MOD($G136+$J135+$C136+$F136,4294967296) -> 963628945 | I136: =MOD($H136,2^(32-$D136))*2^$D136+INT($H136/2^(32-$D136)) -> 3830340595 | J136: =$M135 -> 1538793639 | K136: =MOD($K135+$I136,4294967296) -> 1094714429 | L136: =$K135 -> 1559341130 | M136: =$L135 -> 2474143782
A137: 3 | B137: 4 | C137: =INDEX(Sheet2!$B$2:$B$65,$B137+1) -> 4118548399 | D137: =INDEX(Sheet2!$C$2:$C$65,$B137+1) -> 7 | E137: =INDEX(Sheet2!$D$2:$D$65,$B137+1) -> 4 | F137: =INDEX(Sheet3!$AY$2:$BN$11,$A137,$E137+1) -> 2151628607 | G137: =IF($B137<16,_xlfn.BITOR(_xlfn.BITAND($K136,$L136),_xlfn.BITAND(4294967295-$K136,$M136)),IF($B137<32,_xlfn.BITOR(_xlfn.BITAND($M136,$K136),_xlfn.BITAND(4294967295-$M136,$L136)),IF($B137<48,_xlfn.BITXOR(_xlfn.BITXOR($K136,$L136),$M136),_xlfn.BITXOR($L136,_xlfn.BITOR($K136,4294967295-$M136))))) -> 3531108362 | H137: =MOD($G137+$J136+$C137+$F137,4294967296) -> 2750144415 | I137: =MOD($H137,2^(32-$D137))*2^$D137+INT($H137/2^(32-$D137)) -> 4126134225 | J137: =$M136 -> 2474143782 | K137: =MOD($K136+$I137,4294967296) -> 925881358 | L137: =$K136 -> 1094714429 | M137: =$L136 -> 1559341130
A138: 3 | B138: 5 | C138: =INDEX(Sheet2!$B$2:$B$65,$B138+1) -> 1200080426 | D138: =INDEX(Sheet2!$C$2:$C$65,$B138+1) -> 12 | E138: =INDEX(Sheet2!$D$2:$D$65,$B138+1) -> 5 | F138: =INDEX(Sheet3!$AY$2:$BN$11,$A138,$E138+1) -> 0 | G138: =IF($B138<16,_xlfn.BITOR(_xlfn.BITAND($K137,$L137),_xlfn.BITAND(4294967295-$K137,$M137)),IF($B138<32,_xlfn.BITOR(_xlfn.BITAND($M137,$K137),_xlfn.BITAND(4294967295-$M137,$L137)),IF($B138<48,_xlfn.BITXOR(_xlfn.BITXOR($K137,$L137),$M137),_xlfn.BITXOR($L137,_xlfn.BITOR($K137,4294967295-$M137))))) -> 1238379596 | H138: =MOD($G138+$J137+$C138+$F138,4294967296) -> 617636508 | I138: =MOD($H138,2^(32-$D138))*2^$D138+INT($H138/2^(32-$D138)) -> 103400013 | J138: =$M137 -> 1559341130 | K138: =MOD($K137+$I138,4294967296) -> 1029281371 | L138: =$K137 -> 925881358 | M138: =$L137 -> 1094714429
A139: 3 | B139: 6 | C139: =INDEX(Sheet2!$B$2:$B$65,$B139+1) -> 2821735955 | D139: =INDEX(Sheet2!$C$2:$C$65,$B139+1) -> 17 | E139: =INDEX(Sheet2!$D$2:$D$65,$B139+1) -> 6 | F139: =INDEX(Sheet3!$AY$2:$BN$11,$A139,$E139+1) -> 0 | G139: =IF($B139<16,_xlfn.BITOR(_xlfn.BITAND($K138,$L138),_xlfn.BITAND(4294967295-$K138,$M138)),IF($B139<32,_xlfn.BITOR(_xlfn.BITAND($M138,$K138),_xlfn.BITAND(4294967295-$M138,$L138)),IF($B139<48,_xlfn.BITXOR(_xlfn.BITXOR($K138,$L138),$M138),_xlfn.BITXOR($L138,_xlfn.BITOR($K138,4294967295-$M138))))) -> 1963562030 | H139: =MOD($G139+$J138+$C139+$F139,4294967296) -> 2049671819 | I139: =MOD($H139,2^(32-$D139))*2^$D139+INT($H139/2^(32-$D139)) -> 85390423 | J139: =$M138 -> 1094714429 | K139: =MOD($K138+$I139,4294967296) -> 1114671794 | L139: =$K138 -> 1029281371 | M139: =$L138 -> 925881358
A140: 3 | B140: 7 | C140: =INDEX(Sheet2!$B$2:$B$65,$B140+1) -> 4249261313 | D140: =INDEX(Sheet2!$C$2:$C$65,$B140+1) -> 22 | E140: =INDEX(Sheet2!$D$2:$D$65,$B140+1) -> 7 | F140: =INDEX(Sheet3!$AY$2:$BN$11,$A140,$E140+1) -> 0 | G140: =IF($B140<16,_xlfn.BITOR(_xlfn.BITAND($K139,$L139),_xlfn.BITAND(4294967295-$K139,$M139)),IF($B140<32,_xlfn.BITOR(_xlfn.BITAND($M139,$K139),_xlfn.BITAND(4294967295-$M139,$L139)),IF($B140<48,_xlfn.BITXOR(_xlfn.BITXOR($K139,$L139),$M139),_xlfn.BITXOR($L139,_xlfn.BITOR($K139,4294967295-$M139))))) -> 895473182 | H140: =MOD($G140+$J139+$C140+$F140,4294967296) -> 1944481628 | I140: =MOD($H140,2^(32-$D140))*2^$D140+INT($H140/2^(32-$D140)) -> 3609000347 | J140: =$M139 -> 925881358 | K140: =MOD($K139+$I140,4294967296) -> 428704845 | L140: =$K139 -> 1114671794 | M140: =$L139 -> 1029281371
A141: 3 | B141: 8 | C141: =INDEX(Sheet2!$B$2:$B$65,$B141+1) -> 1770035416 | D141: =INDEX(Sheet2!$C$2:$C$65,$B141+1) -> 7 | E141: =INDEX(Sheet2!$D$2:$D$65,$B141+1) -> 8 | F141: =INDEX(Sheet3!$AY$2:$BN$11,$A141,$E141+1) -> 0 | G141: =IF($B141<16,_xlfn.BITOR(_xlfn.BITAND($K140,$L140),_xlfn.BITAND(4294967295-$K140,$M140)),IF($B141<32,_xlfn.BITOR(_xlfn.BITAND($M140,$K140),_xlfn.BITAND(4294967295-$M140,$L140)),IF($B141<48,_xlfn.BITXOR(_xlfn.BITXOR($K140,$L140),$M140),_xlfn.BITXOR($L140,_xlfn.BITOR($K140,4294967295-$M140))))) -> 609260050 | H141: =MOD($G141+$J140+$C141+$F141,4294967296) -> 3305176824 | I141: =MOD($H141,2^(32-$D141))*2^$D141+INT($H141/2^(32-$D141)) -> 2155838562 | J141: =$M140 -> 1029281371 | K141: =MOD($K140+$I141,4294967296) -> 2584543407 | L141: =$K140 -> 428704845 | M141: =$L140 -> 1114671794
A142: 3 | B142: 9 | C142: =INDEX(Sheet2!$B$2:$B$65,$B142+1) -> 2336552879 | D142: =INDEX(Sheet2!$C$2:$C$65,$B142+1) -> 12 | E142: =INDEX(Sheet2!$D$2:$D$65,$B142+1) -> 9 | F142: =INDEX(Sheet3!$AY$2:$BN$11,$A142,$E142+1) -> 0 | G142: =IF($B142<16,_xlfn.BITOR(_xlfn.BITAND($K141,$L141),_xlfn.BITAND(4294967295-$K141,$M141)),IF($B142<32,_xlfn.BITOR(_xlfn.BITAND($M141,$K141),_xlfn.BITAND(4294967295-$M141,$L141)),IF($B142<48,_xlfn.BITXOR(_xlfn.BITXOR($K141,$L141),$M141),_xlfn.BITXOR($L141,_xlfn.BITOR($K141,4294967295-$M141))))) -> 1484622365 | H142: =MOD($G142+$J141+$C142+$F142,4294967296) -> 555489319 | I142: =MOD($H142,2^(32-$D142))*2^$D142+INT($H142/2^(32-$D142)) -> 3246551569 | J142: =$M141 -> 1114671794 | K142: =MOD($K141+$I142,4294967296) -> 1536127680 | L142: =$K141 -> 2584543407 | M142: =$L141 -> 428704845
...
